<?xml version="1.0" encoding="utf-8"?>
<!-- This URDF was automatically created by SolidWorks to URDF Exporter! Originally created by Stephen Brawner (brawner@gmail.com) 
     Commit Version: 1.6.0-4-g7f85cfe  Build Version: 1.6.7995.38578
     For more information, please see http://wiki.ros.org/sw_urdf_exporter -->
<robot
  name="bot" xmlns:xacro="http://ros.org/wiki/xacro">

  <link name="dummy_link"></link>

  <link
    name="base_link">
    <inertial>
      <origin
        xyz="5.29525990393162E-17 -9.73800707817418E-06 -0.0635"
        rpy="0 0 0" />
      <mass
        value="55.6598235139156" />
      <inertia
        ixx="2.81267028933357"
        ixy="3.63939496425514E-15"
        ixz="3.94988671822613E-17"
        iyy="1.95078014130375"
        iyz="1.85215970484754E-14"
        izz="4.60246220409625" />
    </inertial>
    <visual>
      <origin
        xyz="0 0 0"
        rpy="0 0 0" />
      <geometry>
        <mesh
          filename="package://bot/meshes/base_link.STL" />
      </geometry>
      <material
        name="">
        <color
          rgba="0.792156862745098 0.819607843137255 0.933333333333333 1" />
      </material>
    </visual>
    <collision>
      <origin
        xyz="0 0 0"
        rpy="0 0 0" />
      <geometry>
        <mesh
          filename="package://bot/meshes/base_link.STL" />
      </geometry>
    </collision>
  </link>
  <joint name="dummy_joint" type="fixed">
      <origin rpy="0 0 0" xyz="0 0 0" />
      <parent link="dummy_link"/>
      <child link="base_link"/>
  </joint>
  <link
    name="front_right_wheel">
    <inertial>
      <origin
        xyz="0 -2.77555756156289E-17 0"
        rpy="0 0 0" />
      <mass
        value="2.57407399381529" />
      <inertia
        ixx="0.0120399994394116"
        ixy="8.87665937757815E-18"
        ixz="-2.59581749825777E-22"
        iyy="0.00947976967355967"
        iyz="-7.28360102040025E-22"
        izz="0.00947976967355967" />
    </inertial>
    <visual>
      <origin
        xyz="0 0 0"
        rpy="0 0 0" />
      <geometry>
        <mesh
          filename="package://bot/meshes/front_right_wheel.STL" />
      </geometry>
      <material
        name="">
        <color
          rgba="0.792156862745098 0.819607843137255 0.933333333333333 1" />
      </material>
    </visual>
    <collision>
      <origin
        xyz="0 0 0"
        rpy="0 0 0" />
      <geometry>
        <mesh
          filename="package://bot/meshes/front_right_wheel.STL" />
      </geometry>
    </collision>
  </link>
  <joint
    name="front_right_joint"
    type="continuous">
    <origin
      xyz="0.380999999999999 0.203308839419647 -0.0635"
      rpy="0 0 0" />
    <parent
      link="base_link" />
    <child
      link="front_right_wheel" />
    <axis
      xyz="-1 0 0" />
    <limit
      effort="100"
      velocity="100" />
    <dynamics
      friction="2" />
  </joint>
  <link
    name="front_left_wheel">
    <inertial>
      <origin
        xyz="7.21644966006352E-16 -5.82867087928207E-16 -4.42701431069281E-15"
        rpy="0 0 0" />
      <mass
        value="2.57407399381529" />
      <inertia
        ixx="0.0120399994394116"
        ixy="4.53870443951435E-32"
        ixz="-4.30715293273093E-32"
        iyy="0.00947976967355967"
        iyz="3.33476871334018E-19"
        izz="0.00947976967355967" />
    </inertial>
    <visual>
      <origin
        xyz="0 0 0"
        rpy="0 0 0" />
      <geometry>
        <mesh
          filename="package://bot/meshes/front_left_wheel.STL" />
      </geometry>
      <material
        name="">
        <color
          rgba="0.792156862745098 0.819607843137255 0.933333333333333 1" />
      </material>
    </visual>
    <collision>
      <origin
        xyz="0 0 0"
        rpy="0 0 0" />
      <geometry>
        <mesh
          filename="package://bot/meshes/front_left_wheel.STL" />
      </geometry>
    </collision>
  </link>
  <joint
    name="front_left_joint"
    type="continuous">
    <origin
      xyz="-0.381000000000001 0.203308839419646 -0.0634999999999956"
      rpy="0 0 0" />
    <parent
      link="base_link" />
    <child
      link="front_left_wheel" />
    <axis
      xyz="-1 0 0" />
    <limit
      effort="100"
      velocity="100" />
    <dynamics
      friction="2" />
  </joint>
  <link
    name="rear_right_wheel">
    <inertial>
      <origin
        xyz="0 1.38777878078145E-16 -5.55111512312578E-17"
        rpy="0 0 0" />
      <mass
        value="2.57407399381529" />
      <inertia
        ixx="0.0120399994394116"
        ixy="-8.23857166437262E-18"
        ixz="-8.99778474588208E-18"
        iyy="0.00947976967355967"
        iyz="2.0080327736242E-19"
        izz="0.00947976967355967" />
    </inertial>
    <visual>
      <origin
        xyz="0 0 0"
        rpy="0 0 0" />
      <geometry>
        <mesh
          filename="package://bot/meshes/rear_right_wheel.STL" />
      </geometry>
      <material
        name="">
        <color
          rgba="0.792156862745098 0.819607843137255 0.933333333333333 1" />
      </material>
    </visual>
    <collision>
      <origin
        xyz="0 0 0"
        rpy="0 0 0" />
      <geometry>
        <mesh
          filename="package://bot/meshes/rear_right_wheel.STL" />
      </geometry>
    </collision>
  </link>
  <joint
    name="rear_right_joint"
    type="continuous">
    <origin
      xyz="0.380999999999999 -0.203121668505498 -0.0635000000000014"
      rpy="0 0 0" />
    <parent
      link="base_link" />
    <child
      link="rear_right_wheel" />
    <axis
      xyz="-1 0 0" />
    <limit
      effort="100"
      velocity="100" />
    <dynamics
      friction="2" />
  </joint>
  <link
    name="rear_left_wheel">
    <inertial>
      <origin
        xyz="5.55111512312578E-17 0 0"
        rpy="0 0 0" />
      <mass
        value="2.57407399381529" />
      <inertia
        ixx="0.0120399994394116"
        ixy="5.57553803391328E-32"
        ixz="-2.29959203264697E-32"
        iyy="0.00947976967355968"
        iyz="2.83276051993413E-19"
        izz="0.00947976967355968" />
    </inertial>
    <visual>
      <origin
        xyz="0 0 0"
        rpy="0 0 0" />
      <geometry>
        <mesh
          filename="package://bot/meshes/rear_left_wheel.STL" />
      </geometry>
      <material
        name="">
        <color
          rgba="0.792156862745098 0.819607843137255 0.933333333333333 1" />
      </material>
    </visual>
    <collision>
      <origin
        xyz="0 0 0"
        rpy="0 0 0" />
      <geometry>
        <mesh
          filename="package://bot/meshes/rear_left_wheel.STL" />
      </geometry>
    </collision>
  </link>
  <joint
    name="rear_left_joint"
    type="continuous">
    <origin
      xyz="-0.381 -0.203121668505497 -0.0635"
      rpy="0 0 0" />
    <parent
      link="base_link" />
    <child
      link="rear_left_wheel" />
    <axis
      xyz="1 0 0" />
  </joint>
      <limit
      effort="100"
      velocity="100" />
    <dynamics
      friction="2" />
  <link
    name="base">
    <inertial>
      <origin
        xyz="0.00511718765304885 -0.0112421140263127 0.0184342922607056"
        rpy="0 0 0" />
      <mass
        value="0.723083512259377" />
      <inertia
        ixx="0.00116920742375109"
        ixy="8.83617986414143E-07"
        ixz="3.01864966968444E-07"
        iyy="0.00119718617941842"
        iyz="-9.31078928745321E-08"
        izz="0.00219015492473889" />
    </inertial>
    <visual>
      <origin
        xyz="0 0 0"
        rpy="0 0 0" />
      <geometry>
        <mesh
          filename="package://bot/meshes/base.STL" />
      </geometry>
      <material
        name="">
        <color
          rgba="1 1 1 1" />
      </material>
    </visual>
    <collision>
      <origin
        xyz="0 0 0"
        rpy="0 0 0" />
      <geometry>
        <mesh
          filename="package://bot/meshes/base.STL" />
      </geometry>
    </collision>
  </link>
  <joint
    name="base_joint"
    type="fixed">
    <origin
      xyz="0 0 0"
      rpy="0 0 -3.14159265358979" />
    <parent
      link="base_link" />
    <child
      link="base" />
    <axis
      xyz="0 0 1" />
  </joint>
  <link
    name="base_upper">
    <inertial>
      <origin
        xyz="-0.0116117632132717 0.000383364243673485 0.0782893466923685"
        rpy="0 0 0" />
      <mass
        value="0.31351415705449" />
      <inertia
        ixx="0.00109350112538256"
        ixy="2.63698124767234E-06"
        ixz="8.76014869023999E-05"
        iyy="0.00117081942764081"
        iyz="-2.87530318626991E-06"
        izz="0.00103229366355183" />
    </inertial>
    <visual>
      <origin
        xyz="0 0 0"
        rpy="0 0 0" />
      <geometry>
        <mesh
          filename="package://bot/meshes/base_upper.STL" />
      </geometry>
      <material
        name="">
        <color
          rgba="0.698039215686274 0.698039215686274 0.698039215686274 1" />
      </material>
    </visual>
    <collision>
      <origin
        xyz="0 0 0"
        rpy="0 0 0" />
      <geometry>
        <mesh
          filename="package://bot/meshes/base_upper.STL" />
      </geometry>
    </collision>
  </link>
  <joint
    name="base_upper_joint"
    type="revolute">
    <origin
      xyz="0.0055859808542799 -0.011250305311917 0.0382"
      rpy="0 0 3.14159265358979" />
    <parent
      link="base" />
    <child
      link="base_upper" />
    <axis
      xyz="0 0 1" />
    <limit
      lower="-360"
      upper="360"
      effort="330"
      velocity="120" />
  </joint>
  <link
    name="stem1_lower">
    <inertial>
      <origin
        xyz="-0.250964029617767 1.36109700881078E-06 -0.0743401764727535"
        rpy="0 0 0" />
      <mass
        value="0.887803819596514" />
      <inertia
        ixx="0.0020597159798526"
        ixy="-1.87780190669962E-06"
        ixz="-0.000425002749237477"
        iyy="0.0463634511155588"
        iyz="-5.14657805766743E-07"
        izz="0.0461704800267664" />
    </inertial>
    <visual>
      <origin
        xyz="0 0 0"
        rpy="0 0 0" />
      <geometry>
        <mesh
          filename="package://bot/meshes/stem1_lower.STL" />
      </geometry>
      <material
        name="">
        <color
          rgba="0.698039215686274 0.698039215686274 0.698039215686274 1" />
      </material>
    </visual>
    <collision>
      <origin
        xyz="0 0 0"
        rpy="0 0 0" />
      <geometry>
        <mesh
          filename="package://bot/meshes/stem1_lower.STL" />
      </geometry>
    </collision>
  </link>
  <joint
    name="stem1_lower_joint"
    type="revolute">
    <origin
      xyz="-0.09594811009797 0.00315597348338537 0.0897999999999999"
      rpy="0.0328806482127058 1.5707963267949 0" />
    <parent
      link="base_upper" />
    <child
      link="stem1_lower" />
    <axis
      xyz="0 0 1" />
    <limit
      lower="-360"
      upper="360"
      effort="330"
      velocity="120" />
  </joint>
  <link
    name="stem2_lower">
    <inertial>
      <origin
        xyz="0.256850618540592 -3.26512589751693E-06 -0.0564751218224952"
        rpy="0 0 0" />
      <mass
        value="0.473747302073662" />
      <inertia
        ixx="0.000614889814096562"
        ixy="-2.93192087394554E-07"
        ixz="-9.68363909731034E-06"
        iyy="0.0203300052680768"
        iyz="-5.58761996812224E-08"
        izz="0.0202932113746919" />
    </inertial>
    <visual>
      <origin
        xyz="0 0 0"
        rpy="0 0 0" />
      <geometry>
        <mesh
          filename="package://bot/meshes/stem2_lower.STL" />
      </geometry>
      <material
        name="">
        <color
          rgba="0.698039215686274 0.698039215686274 0.698039215686274 1" />
      </material>
    </visual>
    <collision>
      <origin
        xyz="0 0 0"
        rpy="0 0 0" />
      <geometry>
        <mesh
          filename="package://bot/meshes/stem2_lower.STL" />
      </geometry>
    </collision>
  </link>
  <joint
    name="stem2_lower_joint"
    type="revolute">
    <origin
      xyz="-0.6129 0 -0.0118907105399999"
      rpy="-3.14159265358979 0 -3.14159265358979" />
    <parent
      link="stem1_lower" />
    <child
      link="stem2_lower" />
    <axis
      xyz="0 0 -1" />
    <limit
      lower="-180"
      upper="180"
      effort="150"
      velocity="180" />
  </joint>
  <link
    name="vaccum_lower">
    <inertial>
      <origin
        xyz="-0.00970309440584227 8.66889685178021E-06 -0.0466153153376092"
        rpy="0 0 0" />
      <mass
        value="0.0742761064829774" />
      <inertia
        ixx="9.01013564472013E-05"
        ixy="-4.92114408278052E-09"
        ixz="-9.24589949071441E-06"
        iyy="0.000113726471823955"
        iyz="-1.33755180157871E-08"
        izz="0.000105196868173974" />
    </inertial>
    <visual>
      <origin
        xyz="0 0 0"
        rpy="0 0 0" />
      <geometry>
        <mesh
          filename="package://bot/meshes/vaccum_lower.STL" />
      </geometry>
      <material
        name="">
        <color
          rgba="0.698039215686274 0.698039215686274 0.698039215686274 1" />
      </material>
    </visual>
    <collision>
      <origin
        xyz="0 0 0"
        rpy="0 0 0" />
      <geometry>
        <mesh
          filename="package://bot/meshes/vaccum_lower.STL" />
      </geometry>
    </collision>
  </link>
  <joint
    name="vaccum_lower_joint"
    type="revolute">
    <origin
      xyz="0.571600428429073 0 0.00180000000000217"
      rpy="3.14159265358979 0 3.14159265358979" />
    <parent
      link="stem2_lower" />
    <child
      link="vaccum_lower" />
    <axis
      xyz="0 0 1" />
    <limit
      lower="-360"
      upper="360"
      effort="56"
      velocity="180" />
  </joint>
  <link
    name="vaccum_base">
    <inertial>
      <origin
        xyz="0.00969805656553854 0.000310414630264828 -0.0464151056417503"
        rpy="0 0 0" />
      <mass
        value="0.0742765947065542" />
      <inertia
        ixx="9.01276790228118E-05"
        ixy="-7.80954851213594E-07"
        ixz="9.24035578495716E-06"
        iyy="0.00011370089721125"
        iyz="3.16848951393263E-07"
        izz="0.000105197088600382" />
    </inertial>
    <visual>
      <origin
        xyz="0 0 0"
        rpy="0 0 0" />
      <geometry>
        <mesh
          filename="package://bot/meshes/vaccum_base.STL" />
      </geometry>
      <material
        name="">
        <color
          rgba="0.698039215686274 0.698039215686274 0.698039215686274 1" />
      </material>
    </visual>
    <collision>
      <origin
        xyz="0 0 0"
        rpy="0 0 0" />
      <geometry>
        <mesh
          filename="package://bot/meshes/vaccum_base.STL" />
      </geometry>
    </collision>
  </link>
  <joint
    name="vaccum_base_joint"
    type="revolute">
    <origin
      xyz="-0.0617000000000023 0 -0.0541999999999998"
      rpy="-1.5707963267949 1.53791567858219 -1.5707963267949" />
    <parent
      link="vaccum_lower" />
    <child
      link="vaccum_base" />
    <axis
      xyz="0 0 -1" />
    <limit
      lower="-360"
      upper="360"
      effort="56"
      velocity="180" />
  </joint>
  <link
    name="vaccum">
    <inertial>
      <origin
        xyz="0.000313181813957038 0.000630023326660956 0.00605165753375556"
        rpy="0 0 0" />
      <mass
        value="0.0268694084652048" />
      <inertia
        ixx="1.26795760219904E-05"
        ixy="8.09177044046923E-09"
        ixz="4.68378058281615E-08"
        iyy="1.37178190546949E-05"
        iyz="-5.25186112249873E-08"
        izz="2.31730256688673E-05" />
    </inertial>
    <visual>
      <origin
        xyz="0 0 0"
        rpy="0 0 0" />
      <geometry>
        <mesh
          filename="package://bot/meshes/vaccum.STL" />
      </geometry>
      <material
        name="">
        <color
          rgba="0.698039215686274 0.698039215686274 0.698039215686274 1" />
      </material>
    </visual>
    <collision>
      <origin
        xyz="0 0 0"
        rpy="0 0 0" />
      <geometry>
        <mesh
          filename="package://bot/meshes/vaccum.STL" />
      </geometry>
    </collision>
  </link>
  <link
    name="vaccum2">
    <inertial>
      <origin
        xyz="0.000313181813957038 0.000630023326660956 0.00605165753375556"
        rpy="0 0 0" />
      <mass
        value="0.0268694084652048" />
      <inertia
        ixx="1.26795760219904E-05"
        ixy="8.09177044046923E-09"
        ixz="4.68378058281615E-08"
        iyy="1.37178190546949E-05"
        iyz="-5.25186112249873E-08"
        izz="2.31730256688673E-05" />
    </inertial>
    <visual>
      <origin
        xyz="0 0 0"
        rpy="0 0 0" />
      <geometry>
        <mesh
          filename="package://bot/meshes/vaccum.STL" />
      </geometry>
      <material
        name="">
        <color
          rgba="0.698039215686274 0.698039215686274 0.698039215686274 1" />
      </material>
    </visual>
    <collision>
      <origin
        xyz="0 0 0"
        rpy="0 0 0" />
      <geometry>
        <mesh
          filename="package://bot/meshes/vaccum.STL" />
      </geometry>
    </collision>
  </link>
  <link
    name="vaccum3">
    <inertial>
      <origin
        xyz="0.000313181813957038 0.000630023326660956 0.00605165753375556"
        rpy="0 0 0" />
      <mass
        value="0.0268694084652048" />
      <inertia
        ixx="1.26795760219904E-05"
        ixy="8.09177044046923E-09"
        ixz="4.68378058281615E-08"
        iyy="1.37178190546949E-05"
        iyz="-5.25186112249873E-08"
        izz="2.31730256688673E-05" />
    </inertial>
    <visual>
      <origin
        xyz="0 0 0"
        rpy="0 0 0" />
      <geometry>
        <mesh
          filename="package://bot/meshes/vaccum.STL" />
      </geometry>
      <material
        name="">
        <color
          rgba="0.698039215686274 0.698039215686274 0.698039215686274 1" />
      </material>
    </visual>
    <collision>
      <origin
        xyz="0 0 0"
        rpy="0 0 0" />
      <geometry>
        <mesh
          filename="package://bot/meshes/vaccum.STL" />
      </geometry>
    </collision>
  </link>
  <link
    name="vaccum4">
    <inertial>
      <origin
        xyz="0.000313181813957038 0.000630023326660956 0.00605165753375556"
        rpy="0 0 0" />
      <mass
        value="0.0268694084652048" />
      <inertia
        ixx="1.26795760219904E-05"
        ixy="8.09177044046923E-09"
        ixz="4.68378058281615E-08"
        iyy="1.37178190546949E-05"
        iyz="-5.25186112249873E-08"
        izz="2.31730256688673E-05" />
    </inertial>
    <visual>
      <origin
        xyz="0 0 0"
        rpy="0 0 0" />
      <geometry>
        <mesh
          filename="package://bot/meshes/vaccum.STL" />
      </geometry>
      <material
        name="">
        <color
          rgba="0.698039215686274 0.698039215686274 0.698039215686274 1" />
      </material>
    </visual>
    <collision>
      <origin
        xyz="0 0 0"
        rpy="0 0 0" />
      <geometry>
        <mesh
          filename="package://bot/meshes/vaccum.STL" />
      </geometry>
    </collision>
  </link>
    <link
    name="vaccum5">
    <inertial>
      <origin
        xyz="0.000313181813957038 0.000630023326660956 0.00605165753375556"
        rpy="0 0 0" />
      <mass
        value="0.0268694084652048" />
      <inertia
        ixx="1.26795760219904E-05"
        ixy="8.09177044046923E-09"
        ixz="4.68378058281615E-08"
        iyy="1.37178190546949E-05"
        iyz="-5.25186112249873E-08"
        izz="2.31730256688673E-05" />
    </inertial>
    <visual>
      <origin
        xyz="0 0 0"
        rpy="0 0 0" />
      <geometry>
        <mesh
          filename="package://bot/meshes/vaccum.STL" />
      </geometry>
      <material
        name="">
        <color
          rgba="0.698039215686274 0.698039215686274 0.698039215686274 1" />
      </material>
    </visual>
    <collision>
      <origin
        xyz="0 0 0"
        rpy="0 0 0" />
      <geometry>
        <mesh
          filename="package://bot/meshes/vaccum.STL" />
      </geometry>
    </collision>
  </link>
  <joint
    name="vaccum_joint"
    type="revolute">
    <origin
      xyz="0.0786574610907338 0.00258724076189991 -0.054"
      rpy="1.5707963267949 0 1.6036769750076" />
    <parent
      link="vaccum_base" />
    <child
      link="vaccum" />
    <axis
      xyz="0 0 1" />
    <limit
      lower="-360"
      upper="360"
      effort="56"
      velocity="180" />
  </joint>
    <link name="camera_link">
    <inertial>
      <mass value="0.1"/>
      <inertia ixx="0.0001" ixy="0" ixz="0" iyy="0.0001" iyz="0" izz="0.0001"/>
    </inertial>
    <visual>
      <origin xyz="0.02969805656553854 -0.000310414630264828 -0.0539151056417503" rpy="0 0 0"/>
      <geometry>
        <box size="0.02 0.02 0.02"/>
      </geometry>
      <material name="black"/>
    </visual>
  </link>

  <joint name="camera_joint" type="fixed">
    <origin xyz="0.02969805656553854 -0.000310414630264828 -0.0539151056417503" rpy="0 0 0"/> 
    <parent link="vaccum_base"/>
    <child link="camera_link"/>
  </joint>
<joint name="vaccum_joint2" type="revolute">
  <origin xyz="0.0786574610907338 0.00258724076189991 -0.054" rpy="1.5707963267949 0 1.6036769750076" />
  <parent link="vaccum_base" />
  <child link="vaccum2" />
  <axis xyz="0 0 -1" />
  <limit lower="-360" upper="360" effort="56" velocity="180" />
</joint>
<joint name="vaccum_joint3" type="revolute">
  <origin xyz="0.0786574610907338 0.00258724076189991 -0.054" rpy="1.5707963267949 0 1.6036769750076" />
  <parent link="vaccum_base" />
  <child link="vaccum3" />
  <axis xyz="0 0 1" />
  <limit lower="-360" upper="360" effort="56" velocity="180" />
</joint>
<joint name="vaccum_joint4" type="revolute">
  <origin xyz="0.0786574610907338 0.00258724076189991 -0.054" rpy="1.5707963267949 0 1.6036769750076" />
  <parent link="vaccum_base" />
  <child link="vaccum4" />
  <axis xyz="0 0 1" />
  <limit lower="-360" upper="360" effort="56" velocity="180" />
</joint>
<joint name="vaccum_joint5" type="revolute">
  <origin xyz="0.0786574610907338 0.00258724076189991 -0.054" rpy="1.5707963267949 0 1.6036769750076" />
  <parent link="vaccum_base" />
  <child link="vaccum5" />
  <axis xyz="0 0 1" />
  <limit lower="-360" upper="360" effort="56" velocity="180" />
</joint>

<ros2_control name="GazeboSystem" type="system">
    <hardware>
        <plugin>gazebo_ros2_control/GazeboSystem</plugin>
    </hardware>

    <!-- Velocity Controllers -->

    <joint name="base_upper_joint">
        <command_interface name="velocity">
            <param name="min">-1000.0</param>
            <param name="max">1000.0</param>
        </command_interface>
        <state_interface name="position"/>
        <state_interface name="velocity"/>
    </joint>

    <joint name="stem1_lower_joint">
        <command_interface name="velocity">
            <param name="min">-1000.0</param>
            <param name="max">1000.0</param>
        </command_interface>
        <state_interface name="position"/>
        <state_interface name="velocity"/>
    </joint>

    <joint name="stem2_lower_joint">
        <command_interface name="velocity">
            <param name="min">-1000.0</param>
            <param name="max">1000.0</param>
        </command_interface>
        <state_interface name="position"/>
        <state_interface name="velocity"/>
    </joint>

    <joint name="vaccum_lower_joint">
        <command_interface name="velocity">
            <param name="min">-1000.0</param>
            <param name="max">1000.0</param>
        </command_interface>
        <state_interface name="position"/>
        <state_interface name="velocity"/>
    </joint>

    <joint name="vaccum_base_joint">
        <command_interface name="velocity">
            <param name="min">-1000.0</param>
            <param name="max">1000.0</param>
        </command_interface>
        <state_interface name="position"/>
        <state_interface name="velocity"/>
    </joint>

    <joint name="vaccum_joint">
        <command_interface name="velocity">
            <param name="min">-1000.0</param>
            <param name="max">1000.0</param>
        </command_interface>
        <state_interface name="position"/>
        <state_interface name="velocity"/>
    </joint>

    <joint name="front_right_joint">
        <command_interface name="velocity">
            <param name="min">-1000.0</param>
            <param name="max">1000.0</param>
        </command_interface>
        <state_interface name="position"/>
        <state_interface name="velocity"/>
    </joint>

    <joint name="front_left_joint">
        <command_interface name="velocity">
            <param name="min">-1000.0</param>
            <param name="max">1000.0</param>
        </command_interface>
        <state_interface name="position"/>
        <state_interface name="velocity"/>
    </joint>

    <joint name="rear_left_joint">
        <command_interface name="velocity">
            <param name="min">-1000.0</param>
            <param name="max">1000.0</param>
        </command_interface>
        <state_interface name="position"/>
        <state_interface name="velocity"/>
    </joint>

    <joint name="rear_right_joint">
        <command_interface name="velocity">
            <param name="min">-1000.0</param>
            <param name="max">1000.0</param>
        </command_interface>
        <state_interface name="position"/>
        <state_interface name="velocity"/>
    </joint>


    <!-- Position Controller -->

    <joint name="base_upper_joint">
        <command_interface name="position">
            <param name="min">-3.14</param>
            <param name="max">3.14</param>
        </command_interface>
        <state_interface name="position"/>
        <state_interface name="velocity"/>
    </joint>

    <joint name="stem1_lower_joint">
        <command_interface name="position">
            <param name="min">-3.14</param>
            <param name="max">3.14</param>
        </command_interface>
        <state_interface name="position"/>
        <state_interface name="velocity"/>
    </joint>

    <joint name="stem2_lower_joint">
        <command_interface name="position">
            <param name="min">-1.57</param>
            <param name="max">1.57</param>
        </command_interface>
        <state_interface name="position"/>
        <state_interface name="velocity"/>
    </joint>

    <joint name="vaccum_lower_joint">
        <command_interface name="position">
            <param name="min">-3.14</param>
            <param name="max">3.14</param>
        </command_interface>
        <state_interface name="position"/>
        <state_interface name="velocity"/>
    </joint>

    <joint name="vaccum_base_joint">
        <command_interface name="position">
            <param name="min">-3.14</param>
            <param name="max">3.14</param>
        </command_interface>
        <state_interface name="position"/>
        <state_interface name="velocity"/>
    </joint>

    <joint name="vaccum_joint">
        <command_interface name="position">
            <param name="min">-3.14</param>
            <param name="max">3.14</param>
        </command_interface>
        <state_interface name="position"/>
        <state_interface name="velocity"/>
    </joint>

  </ros2_control>

  <gazebo>
      <plugin filename="libgazebo_ros2_control.so" name="gazebo_ros2_control">
          <parameters>$(find bot)/config/control.yaml</parameters>
      </plugin>
  </gazebo>

  <gazebo>
    <plugin name='vacuum_gripper' filename='libgazebo_ros_vacuum_gripper.so'>
      <ros>
        <namespace>/bot/vaccum</namespace>
        <remapping>switch:=vaccum_switch</remapping>
        <remapping>grasping:=vaccum_grasping</remapping>
      </ros>
      <link_name>vaccum</link_name>
      <max_distance>0.2</max_distance>
      <fixed>ground_plane</fixed>
      <fixed>wall</fixed>
      <fixed>Ground_Pallete</fixed>
      <fixed>conveyor_belt</fixed>
      <maxForce>10.0</maxForce>
    </plugin>
  </gazebo>
  <gazebo>
    <plugin name='vacuum_gripper2' filename='libgazebo_ros_vacuum_gripper.so'>
      <ros>
        <namespace>/bot/vaccum</namespace>
        <remapping>switch:=vaccum_switch2</remapping>
        <remapping>grasping:=vaccum_grasping2</remapping>
      </ros>
      <link_name>vaccum2</link_name>
      <max_distance>0.2</max_distance>
      <fixed>ground_plane</fixed>
      <fixed>wall</fixed>
      <fixed>Ground_Pallete</fixed>
      <fixed>conveyor_belt</fixed>
      <maxForce>10.0</maxForce>
    </plugin>
  </gazebo>
    <gazebo>
    <plugin name='vacuum_gripper3' filename='libgazebo_ros_vacuum_gripper.so'>
      <ros>
        <namespace>/bot/vaccum</namespace>
        <remapping>switch:=vaccum_switch3</remapping>
        <remapping>grasping:=vaccum_grasping3</remapping>
      </ros>
      <link_name>vaccum3</link_name>
      <max_distance>0.2</max_distance>
      <fixed>ground_plane</fixed>
      <fixed>wall</fixed>
      <fixed>Ground_Pallete</fixed>
      <fixed>conveyor_belt</fixed>
      <maxForce>10.0</maxForce>
    </plugin>
  </gazebo>
    <gazebo>
    <plugin name='vacuum_gripper4' filename='libgazebo_ros_vacuum_gripper.so'>
      <ros>
        <namespace>/bot/vaccum</namespace>
        <remapping>switch:=vaccum_switch4</remapping>
        <remapping>grasping:=vaccum_grasping4</remapping>
      </ros>
      <link_name>vaccum4</link_name>
      <max_distance>0.2</max_distance>
      <fixed>ground_plane</fixed>
      <fixed>wall</fixed>
      <fixed>Ground_Pallete</fixed>
      <fixed>conveyor_belt</fixed>
      <maxForce>10.0</maxForce>
    </plugin>
  </gazebo>
    <gazebo>
    <plugin name='vacuum_gripper5' filename='libgazebo_ros_vacuum_gripper.so'>
      <ros>
        <namespace>/bot/vaccum</namespace>
        <remapping>switch:=vaccum_switch5</remapping>
        <remapping>grasping:=vaccum_grasping5</remapping>
      </ros>
      <link_name>vaccum5</link_name>
      <max_distance>0.2</max_distance>
      <fixed>ground_plane</fixed>
      <fixed>wall</fixed>
      <fixed>Ground_Pallete</fixed>
      <fixed>conveyor_belt</fixed>
      <maxForce>10.0</maxForce>
    </plugin>
  </gazebo>
<!-- <gazebo>
  <plugin filename="libodometry_plugin.so" name="odometry_plugin">
    <frame>base_link</frame>
    <world_frame>fixed_world</world_frame>
  </plugin>
</gazebo> -->
  <gazebo reference="camera_link">
    <sensor name="camera" type="camera">
      <update_rate>20</update_rate>
      <camera>
        <horizontal_fov>1.3962634</horizontal_fov>
        <image>
          <width>800</width>
          <height>800</height>
          <format>R8G8B8</format>
        </image>
        <clip>
          <near>0.02</near>
          <far>800.0</far>
        </clip>
          <noise>
          <type>gaussian</type>
          <mean>0.0</mean>
          <stddev>0.007</stddev>
        </noise>
      </camera>
      <plugin name="camera_link_controller" filename="libgazebo_ros_camera.so">
        <!-- <baseline>0.2</baseline> -->
        <alwaysOn>true</alwaysOn>
        <updateRate>0.0</updateRate>
        <cameraName>camera</cameraName>
        <imageTopicName>image_raw</imageTopicName>
        <cameraInfoTopicName>camera_info</cameraInfoTopicName>
        <!-- <depthImageTopicName>/camera/depth/image_raw</depthImageTopicName>
        <depthImageInfoTopicName>/camera/depth/camera_info</depthImageInfoTopicName>
        <pointCloudTopicName>/camera/depth/points</pointCloudTopicName> -->
        <frameName>camera_link</frameName>
        <hackBaseline>0.0</hackBaseline>
        <!-- <pointCloudCutoff>0.5</pointCloudCutoff>
        <pointCloudCutoffMax>4.0</pointCloudCutoffMax>
        <distortionK1>0.00000001</distortionK1>
        <distortionK2>0.00000001</distortionK2>
        <distortionK3>0.00000001</distortionK3>
        <distortionT1>0.00000001</distortionT1>
        <distortionT2>0.00000001</distortionT2> -->
        <CxPrime>0</CxPrime>
        <Cx>0</Cx>
        <Cy>0</Cy>
        <focalLength>0</focalLength>
        <hackBaseline>0</hackBaseline>
      </plugin>
    </sensor>
  </gazebo>
  <gazebo reference="base_link">
  <gravity>true</gravity>
  <sensor name="imu_sensor" type="imu">
    <always_on>true</always_on>
    <update_rate>100</update_rate>
    <visualize>true</visualize>
    <topic>__default_topic__</topic>
    <plugin filename="libgazebo_ros_imu_sensor.so" name="imu_plugin">
      <topicName>imu</topicName>
      <bodyName>base_link</bodyName>
      <updateRateHZ>10.0</updateRateHZ>
      <gaussianNoise>0.0</gaussianNoise>
      <xyzOffset>0 0 0</xyzOffset>
      <rpyOffset>0 0 0</rpyOffset>
      <frameName>base_link</frameName>
      <initialOrientationAsReference>false</initialOrientationAsReference>
    </plugin>
    <pose>0 0 0 0 0 0</pose>
  </sensor>
</gazebo>
</robot>